<?xml version="1.0" encoding="utf-8"?>
<!-- =================================================================================== -->
<!-- |    This document was autogenerated by xacro from raspimouse_realsense.urdf.xacro | -->
<!-- |    EDITING THIS FILE BY HAND IS NOT RECOMMENDED                                 | -->
<!-- =================================================================================== -->
<robot name="raspimouse_sim" xmlns:xacro="http://ros.org/wiki/xacro">
  <!-- =============== Link & Joint =============== -->
  <!-- Base -->
  <link name="base_footprint"/>
  <joint name="base_joint" type="fixed">
    <origin xyz="0 0 0.00185"/>
    <parent link="base_footprint"/>
    <child link="base_link"/>
  </joint>
  <link name="base_link">
    <visual>
      <geometry>
        <mesh filename="package://raspimouse_description/meshes/stl/RasPiMouse_base_and_RealSenseD435.stl"/>
      </geometry>
    </visual>
    <collision>
      <geometry>
        <mesh filename="package://raspimouse_description/meshes/stl/RasPiMouse_base_and_RealSenseD435.stl"/>
      </geometry>
    </collision>
    <inertial>
      <!-- NOTE BEGINNING -->
      <!-- Biased origin causes the slipping problem. -->
      <!-- Not solved yet. -->
      <!-- NOTE END -->
      <!-- real origin -->
      <!-- <origin xyz="&#45;0.005075 &#45;0.000427 0.029879"/> -->
      <!-- virtual origin -->
      <origin xyz="-0.001 0.0 0.029879"/>
      <mass value="0.7186"/>
      <inertia ixx="0.001238161833" ixy="0.000000904986" ixz="0.000100297310" iyy="0.001368529369" iyz="0.000022118177" izz="0.000784319117"/>
    </inertial>
  </link>
  <joint name="right_wheel_joint" type="continuous">
    <origin rpy="1.57 0 0" xyz="0 -0.0425 0.02215"/>
    <axis xyz="0 0 -1"/>
    <parent link="base_link"/>
    <child link="right_wheel"/>
    <limit effort="70" velocity="15"/>
    <safety_controller k_velocity="10"/>
    <dynamics damping="1.0" friction="1.0"/>
  </joint>
  <link name="right_wheel">
    <visual>
      <geometry>
        <mesh filename="package://raspimouse_description/meshes/dae/wheel/RasPiMouse_wheel.dae"/>
      </geometry>
    </visual>
    <collision>
      <!-- <xacro:insert_block name="joint_origin"/> -->
      <geometry>
        <cylinder length="0.01" radius="0.0249"/>
        <!--<mesh filename="package://raspimouse_description/meshes/dae/wheel/RasPiMouse_wheel.dae"/>-->
      </geometry>
    </collision>
    <inertial>
      <origin xyz="-0.000107 0 0.002875"/>
      <mass value="0.0113"/>
      <inertia ixx="0.000002208187" ixy="0.000000000001" ixz="0.000000004787" iyy="0.00000218412" iyz="0.000000000003" izz="0.000004078299"/>
    </inertial>
  </link>
  <joint name="left_wheel_joint" type="continuous">
    <origin rpy="-1.57 0 0" xyz="0 0.0425 0.02215"/>
    <axis xyz="0 0 1"/>
    <parent link="base_link"/>
    <child link="left_wheel"/>
    <limit effort="70" velocity="15"/>
    <safety_controller k_velocity="10"/>
    <dynamics damping="1.0" friction="1.0"/>
  </joint>
  <link name="left_wheel">
    <visual>
      <geometry>
        <mesh filename="package://raspimouse_description/meshes/dae/wheel/RasPiMouse_wheel.dae"/>
      </geometry>
    </visual>
    <collision>
      <!-- <xacro:insert_block name="joint_origin"/> -->
      <geometry>
        <cylinder length="0.01" radius="0.0249"/>
        <!--
        <mesh filename="package://raspimouse_description/meshes/dae/wheel/RasPiMouse_wheel.dae"/>
        -->
      </geometry>
    </collision>
    <inertial>
      <origin xyz="-0.000107 0 0.002875"/>
      <mass value="0.0113"/>
      <inertia ixx="0.000002208187" ixy="0.000000000001" ixz="0.000000004787" iyy="0.00000218412" iyz="0.000000000003" izz="0.000004078299"/>
    </inertial>
  </link>
  <joint name="rf_joint" type="fixed">
    <origin rpy="0 0 0" xyz="0.04 -0.045 0.032"/>
    <parent link="base_link"/>
    <child link="rf"/>
  </joint>
  <link name="rf">
    <visual>
      <geometry>
        <box size="0.01 0.005 0.007"/>
      </geometry>
    </visual>
    <material name="grey">
      <color rgba="0.5 0.5 0.5 1"/>
    </material>
    <inertial>
      <mass value="0.000001"/>
      <origin xyz="0 0 0"/>
      <inertia ixx="0.0001" ixy="0.0" ixz="0.0" iyy="0.0001" iyz="0.0" izz="0.0001"/>
    </inertial>
  </link>
  <joint name="rs_joint" type="fixed">
    <origin rpy="0 0 -1.04" xyz="0.059 -0.01 0.032"/>
    <parent link="base_link"/>
    <child link="rs"/>
  </joint>
  <link name="rs">
    <visual>
      <geometry>
        <box size="0.01 0.005 0.007"/>
      </geometry>
    </visual>
    <material name="grey">
      <color rgba="0.5 0.5 0.5 1"/>
    </material>
    <inertial>
      <mass value="0.000001"/>
      <origin xyz="0 0 0"/>
      <inertia ixx="0.0001" ixy="0.0" ixz="0.0" iyy="0.0001" iyz="0.0" izz="0.0001"/>
    </inertial>
  </link>
  <joint name="ls_joint" type="fixed">
    <origin rpy="0 0 1.04" xyz="0.059 0.01 0.032"/>
    <parent link="base_link"/>
    <child link="ls"/>
  </joint>
  <link name="ls">
    <visual>
      <geometry>
        <box size="0.01 0.005 0.007"/>
      </geometry>
    </visual>
    <material name="grey">
      <color rgba="0.5 0.5 0.5 1"/>
    </material>
    <inertial>
      <mass value="0.000001"/>
      <origin xyz="0 0 0"/>
      <inertia ixx="0.0001" ixy="0.0" ixz="0.0" iyy="0.0001" iyz="0.0" izz="0.0001"/>
    </inertial>
  </link>
  <joint name="lf_joint" type="fixed">
    <origin rpy="0 0 0" xyz="0.04 0.045 0.032"/>
    <parent link="base_link"/>
    <child link="lf"/>
  </joint>
  <link name="lf">
    <visual>
      <geometry>
        <box size="0.01 0.005 0.007"/>
      </geometry>
    </visual>
    <material name="grey">
      <color rgba="0.5 0.5 0.5 1"/>
    </material>
    <inertial>
      <mass value="0.000001"/>
      <origin xyz="0 0 0"/>
      <inertia ixx="0.0001" ixy="0.0" ixz="0.0" iyy="0.0001" iyz="0.0" izz="0.0001"/>
    </inertial>
  </link>
  <raspimouse_sim/>
</robot>

